<?xml version="1.0" ?>
<!-- =================================================================================== -->
<!-- |    This document was autogenerated by xacro from pepper_robot.xacro             | -->
<!-- |    EDITING THIS FILE BY HAND IS NOT RECOMMENDED                                 | -->
<!-- =================================================================================== -->
<!--******************************************************************
 ****** File automatically generated by generate_urdf.py script ******
 *********************************************************************-->
<robot name="JulietteY20MP" xmlns:xacro="http://www.ros.org/wiki/xacro">

  <link name="base_link"/>

  <link name="Tibia">
    <inertial>
      <mass value="11.6015"/>
      <inertia ixx="0.129229" ixy="-0.000401943" ixz="0.00048556" iyy="0.122839" iyz="-1.01666e-08" izz="0.108168"/>
      <origin rpy="0 0 0" xyz="0.00220451 0 0.082271"/>
    </inertial>
    <visual>
      <geometry>
        <mesh filename="package://pepper_description/meshes/KneePitch.dae" scale="0.1 0.1 0.1"/>
      </geometry>
      <origin rpy="0 0 0" xyz="0 0 0"/>
    </visual>
    <collision>
      <geometry>
        <mesh filename="package://pepper_description/meshes/KneePitch_0.10.stl" scale="0.1 0.1 0.1"/>
      </geometry>
      <origin rpy="0 0 0" xyz="0 0 0"/>
    </collision>
  </link>

  <joint name="base_joint" type="fixed">
    <origin rpy="0 0 0" xyz="0 0 0.334"/>
    <parent link="base_link"/>
    <child link="Tibia"/>
  </joint>

  <link name="Pelvis">
    <inertial>
      <mass value="2.45917"/>
      <inertia ixx="0.034351" ixy="0" ixz="0.000223034" iyy="0.0303122" iyz="-8.37542e-05" izz="0.0143771"/>
      <origin rpy="0 0 0" xyz="0.00237 0 -0.01754"/>
    </inertial>
    <visual>
      <geometry>
        <mesh filename="package://pepper_description/meshes/HipPitch.dae" scale="0.1 0.1 0.1"/>
      </geometry>
      <origin rpy="0 0 0" xyz="0 0 0.268"/>
    </visual>
    <collision>
      <geometry>
        <mesh filename="package://pepper_description/meshes/HipPitch_0.10.stl" scale="0.1 0.1 0.1"/>
      </geometry>
      <origin rpy="0 0 0" xyz="0 0 0.268"/>
    </collision>
  </link>

  <joint name="KneePitch" type="revolute">
    <origin rpy="0 0 0" xyz="0 0 0"/>
    <parent link="Tibia"/>
    <child link="Pelvis"/>
    <axis xyz="0 -1.0 0"/>
    <limit effort="27.702" lower="-0.514872" upper="0.514872" velocity="2.93276"/>
  </joint>

  <link name="Hip">
    <inertial>
      <mass value="1.02338"/>
      <inertia ixx="0.00502422" ixy="0" ixz="-2.54911e-05" iyy="0.00640971" iyz="0.000159449" izz="0.00441082"/>
      <origin rpy="0 0 0" xyz="0.00032 0 -0.07068"/>
    </inertial>
    <visual>
      <geometry>
        <mesh filename="package://pepper_description/meshes/HipRoll.dae" scale="0.1 0.1 0.1"/>
      </geometry>
      <origin rpy="0 0 0" xyz="0 0 0.079"/>
    </visual>
    <collision>
      <geometry>
        <mesh filename="package://pepper_description/meshes/HipRoll_0.10.stl" scale="0.1 0.1 0.1"/>
      </geometry>
      <origin rpy="0 0 0" xyz="0 0 0.079"/>
    </collision>
  </link>

  <joint name="HipPitch" type="revolute">
    <origin rpy="0 0 0" xyz="0 0 0.268"/>
    <parent link="Pelvis"/>
    <child link="Hip"/>
    <axis xyz="0 -1.0 0"/>
    <limit effort="19.787" lower="-1.03847" upper="1.03847" velocity="2.93276"/>
  </joint>

  <link name="HipOffset"/>

  <joint name="HipRoll" type="revolute">
    <origin rpy="0 0 0" xyz="-2e-05 0 0.079"/>
    <parent link="Hip"/>
    <child link="HipOffset"/>
    <axis xyz="-1.0 0 0"/>
    <limit effort="10.1884" lower="-0.514872" upper="0.514872" velocity="2.27032"/>
  </joint>

  <link name="torso">
    <inertial>
      <mass value="3.99533"/>
      <inertia ixx="0.0452761" ixy="0" ixz="0.00499091" iyy="0.0432702" iyz="-0.000266886" izz="0.0258881"/>
      <origin rpy="0 0 0" xyz="0.00322 0 -0.01029"/>
    </inertial>
    <visual>
      <geometry>
        <mesh filename="package://pepper_description/meshes/Torso.dae" scale="0.1 0.1 0.1"/>
      </geometry>
      <origin rpy="0 0 0" xyz="0 0 0"/>
    </visual>
    <collision>
      <geometry>
        <mesh filename="package://pepper_description/meshes/Torso_0.10.stl" scale="0.1 0.1 0.1"/>
      </geometry>
      <origin rpy="0 0 0" xyz="0 0 0"/>
    </collision>
  </link>

  <joint name="hip_fixed" type="fixed">
    <origin rpy="0 0 0" xyz="0 0 0.139"/>
    <parent link="HipOffset"/>
    <child link="torso"/>
  </joint>

  <link name="Neck">
    <inertial>
      <mass value="0.27391"/>
      <inertia ixx="0.000343501" ixy="0" ixz="-1.88563e-05" iyy="0.000493898" iyz="2.09863e-06" izz="0.000215252"/>
      <origin rpy="0 0 0" xyz="-0.00207 0 -0.02636"/>
    </inertial>
    <visual>
      <geometry>
        <mesh filename="package://pepper_description/meshes/HeadYaw.dae" scale="0.1 0.1 0.1"/>
      </geometry>
      <origin rpy="0 0 0" xyz="0 0 0"/>
    </visual>
    <collision>
      <geometry>
        <mesh filename="package://pepper_description/meshes/HeadYaw_0.10.stl" scale="0.1 0.1 0.1"/>
      </geometry>
      <origin rpy="0 0 0" xyz="0 0 0"/>
    </collision>
  </link>

  <joint name="HeadYaw" type="revolute">
    <parent link="torso"/>
    <child link="Neck"/>
    <origin rpy="0 0 0" xyz="-0.038 0 0.1699"/>
    <axis xyz="0 0 1.0"/>
    <limit effort="5.428" lower="-2.08567" upper="2.08567" velocity="7.33998"/>
  </joint>

  <link name="Head">
    <inertial>
      <mass value="1.51893"/>
      <inertia ixx="0.00597209" ixy="0" ixz="0.000125138" iyy="0.0059054" iyz="4.3428e-07" izz="0.00570374"/>
      <origin rpy="0 0 0" xyz="0.00312 0 0.11152"/>
    </inertial>
    <visual>
      <geometry>
        <mesh filename="package://pepper_description/meshes/HeadPitch.dae" scale="0.1 0.1 0.1"/>
      </geometry>
      <origin rpy="0 0 0" xyz="0 0 0"/>
    </visual>
    <collision>
      <geometry>
        <mesh filename="package://pepper_description/meshes/HeadPitch_0.10.stl" scale="0.1 0.1 0.1"/>
      </geometry>
      <origin rpy="0 0 0" xyz="0 0 0"/>
    </collision>
  </link>

  <joint name="HeadPitch" type="revolute">
    <parent link="Neck"/>
    <child link="Head"/>
    <origin rpy="0 0 0" xyz="0 0 0"/>
    <axis xyz="0 1.0 0"/>
    <limit effort="2.666" lower="-0.706858" upper="0.637045" velocity="9.22756"/>
  </joint>

  <link name="LShoulder">
    <inertial>
      <mass value="0.3125"/>
      <inertia ixx="0.000361198" ixy="-1.98347e-06" ixz="6.35907e-07" iyy="0.000137229" iyz="-5.68878e-06" izz="0.000399194"/>
      <origin rpy="0 0 0" xyz="0.00018 -0.01856 0.00099"/>
    </inertial>
    <visual>
      <geometry>
        <mesh filename="package://pepper_description/meshes/LShoulderPitch.dae" scale="0.1 0.1 0.1"/>
      </geometry>
      <origin rpy="0 0 0" xyz="0 0 0"/>
    </visual>
    <collision>
      <geometry>
        <mesh filename="package://pepper_description/meshes/LShoulderPitch_0.10.stl" scale="0.1 0.1 0.1"/>
      </geometry>
      <origin rpy="0 0 0" xyz="0 0 0"/>
    </collision>
  </link>  
  
  <joint name="LShoulderPitch" type="revolute">
    <parent link="torso"/>
    <child link="LShoulder"/>
    <origin rpy="0 0 0" xyz="-0.057 0.14974 0.08682"/>
    <axis xyz="0 1.0 0"/>
    <limit effort="5.428" lower="-2.08567" upper="2.08567" velocity="7.33998"/>
  </joint>

  <link name="LBicep">
    <inertial>
      <mass value="0.50527"/>
      <inertia ixx="0.000500872" ixy="-3.55918e-05" ixz="8.51263e-05" iyy="0.00126284" iyz="9.06813e-06" izz="0.00115718"/>
      <origin rpy="0 0 0" xyz="0.08151 0.01284 -0.01017"/>
    </inertial>
    <visual>
      <geometry>
        <mesh filename="package://pepper_description/meshes/LShoulderRoll.dae" scale="0.1 0.1 0.1"/>
      </geometry>
      <origin rpy="0 0 0" xyz="0 0 0"/>
    </visual>
    <collision>
      <geometry>
        <mesh filename="package://pepper_description/meshes/LShoulderRoll_0.10.stl" scale="0.1 0.1 0.1"/>
      </geometry>
      <origin rpy="0 0 0" xyz="0 0 0"/>
    </collision>
  </link>
  
  <joint name="LShoulderRoll" type="revolute">
    <parent link="LShoulder"/>
    <child link="LBicep"/>
    <origin rpy="0 0 0" xyz="0 0 0"/>
    <axis xyz="0 0 1.0"/>
    <limit effort="2.666" lower="0.00872665" upper="1.56207" velocity="9.22756"/>
  </joint>

  <link name="LElbow">
    <inertial>
      <mass value="0.27495"/>
      <inertia ixx="0.000122971" ixy="9.86024e-07" ixz="-2.55838e-05" iyy="0.000331766" iyz="-1.98925e-06" izz="0.000303047"/>
      <origin rpy="0 0 0" xyz="-0.02297 -0.00019 0.00119"/>
    </inertial>
    <visual>
      <geometry>
        <mesh filename="package://pepper_description/meshes/LElbowYaw.dae" scale="0.1 0.1 0.1"/>
      </geometry>
      <origin rpy="0 0 0" xyz="0 0 0"/>
    </visual>
    <collision>
      <geometry>
        <mesh filename="package://pepper_description/meshes/LElbowYaw_0.10.stl" scale="0.1 0.1 0.1"/>
      </geometry>
      <origin rpy="0 0 0" xyz="0 0 0"/>
    </collision>
  </link>
  
  <joint name="LElbowYaw" type="revolute">
    <parent link="LBicep"/>
    <child link="LElbow"/>
    <origin rpy="0 -0.157079 0" xyz="0.1812 0.015 0.00013"/>
    <axis xyz="1.0 0 0"/>
    <limit effort="5.428" lower="-2.08567" upper="2.08567" velocity="7.33998"/>
  </joint>

  <link name="LForeArm">
    <inertial>
      <mass value="0.16579"/>
      <inertia ixx="0.00156513" ixy="1.47517e-05" ixz="-6.05746e-05" iyy="0.00173219" iyz="-1.7619e-07" izz="0.000273081"/>
      <origin rpy="0 0 0" xyz="0.0593 0.00271 -0.01014"/>
    </inertial>
    <visual>
      <geometry>
        <mesh filename="package://pepper_description/meshes/LElbowRoll.dae" scale="0.1 0.1 0.1"/>
      </geometry>
      <origin rpy="0 0 0" xyz="0 0 0"/>
    </visual>
    <collision>
      <geometry>
        <mesh filename="package://pepper_description/meshes/LElbowRoll_0.10.stl" scale="0.1 0.1 0.1"/>
      </geometry>
      <origin rpy="0 0 0" xyz="0 0 0"/>
    </collision>
  </link>
  
  <joint name="LElbowRoll" type="revolute">
    <parent link="LElbow"/>
    <child link="LForeArm"/>
    <origin rpy="0 0 0" xyz="0 0 0"/>
    <axis xyz="0 0 1.0"/>
    <limit effort="2.666" lower="-1.56207" upper="-0.00872665" velocity="9.22756"/>
  </joint>

  <link name="l_wrist">
    <inertial>
      <mass value="0.27555"/>
      <inertia ixx="0.000151643" ixy="1.06629e-05" ixz="2.89509e-06" iyy="0.000431099" iyz="-3.13715e-06" izz="0.000456172"/>
      <origin rpy="0 0 0" xyz="0.03536 -0.00072 -0.00207"/>
    </inertial>
    <visual>
      <geometry>
        <mesh filename="package://pepper_description/meshes/LWristYaw.dae" scale="0.1 0.1 0.1"/>
      </geometry>
      <origin rpy="0 0 0" xyz="0 0 0"/>
    </visual>
    <collision>
      <geometry>
        <mesh filename="package://pepper_description/meshes/LWristYaw_0.10.stl" scale="0.1 0.1 0.1"/>
      </geometry>
      <origin rpy="0 0 0" xyz="0 0 0"/>
    </collision>
  </link>
  
  <joint name="LWristYaw" type="revolute">
    <parent link="LForeArm"/>
    <child link="l_wrist"/>
    <origin rpy="0 0 0" xyz="0.15 0 0"/>
    <axis xyz="1.0 0 0"/>
    <limit effort="0.2014" lower="-1.82387" upper="1.82387" velocity="17.3835"/>
  </joint>

  <link name="RShoulder">
    <inertial>
      <mass value="0.3125"/>
      <inertia ixx="0.000361198" ixy="1.98347e-06" ixz="6.35907e-07" iyy="0.000137229" iyz="5.68878e-06" izz="0.000399194"/>
      <origin rpy="0 0 0" xyz="0.00018 0.01856 0.00099"/>
    </inertial>
    <visual>
      <geometry>
        <mesh filename="package://pepper_description/meshes/RShoulderPitch.dae" scale="0.1 0.1 0.1"/>
      </geometry>
      <origin rpy="0 0 0" xyz="0 0 0"/>
    </visual>
    <collision>
      <geometry>
        <mesh filename="package://pepper_description/meshes/RShoulderPitch_0.10.stl" scale="0.1 0.1 0.1"/>
      </geometry>
      <origin rpy="0 0 0" xyz="0 0 0"/>
    </collision>
  </link>

  <joint name="RShoulderPitch" type="revolute">
    <parent link="torso"/>
    <child link="RShoulder"/>
    <origin rpy="0 0 0" xyz="-0.057 -0.14974 0.08682"/>
    <axis xyz="0 1.0 0"/>
    <limit effort="5.428" lower="-2.08567" upper="2.08567" velocity="7.33998"/>
  </joint>

  <link name="RBicep">
    <inertial>
      <mass value="0.50527"/>
      <inertia ixx="0.000500872" ixy="3.55918e-05" ixz="8.51263e-05" iyy="0.00126284" iyz="-9.06813e-06" izz="0.00115718"/>
      <origin rpy="0 0 0" xyz="0.08151 -0.01284 -0.01017"/>
    </inertial>
    <visual>
      <geometry>
        <mesh filename="package://pepper_description/meshes/RShoulderRoll.dae" scale="0.1 0.1 0.1"/>
      </geometry>
      <origin rpy="0 0 0" xyz="0 0 0"/>
    </visual>
    <collision>
      <geometry>
        <mesh filename="package://pepper_description/meshes/RShoulderRoll_0.10.stl" scale="0.1 0.1 0.1"/>
      </geometry>
      <origin rpy="0 0 0" xyz="0 0 0"/>
    </collision>
  </link>
  
  <joint name="RShoulderRoll" type="revolute">
    <parent link="RShoulder"/>
    <child link="RBicep"/>
    <origin rpy="0 0 0" xyz="0 0 0"/>
    <axis xyz="0 0 1.0"/>
    <limit effort="2.666" lower="-1.56207" upper="-0.00872665" velocity="9.22756"/>
  </joint>

  <link name="RElbow">
    <inertial>
      <mass value="0.27495"/>
      <inertia ixx="0.000122971" ixy="-9.86024e-07" ixz="-2.55838e-05" iyy="0.000331766" iyz="1.98925e-06" izz="0.000303047"/>
      <origin rpy="0 0 0" xyz="-0.02297 0.00019 0.00119"/>
    </inertial>
    <visual>
      <geometry>
        <mesh filename="package://pepper_description/meshes/RElbowYaw.dae" scale="0.1 0.1 0.1"/>
      </geometry>
      <origin rpy="0 0 0" xyz="0 0 0"/>
    </visual>
    <collision>
      <geometry>
        <mesh filename="package://pepper_description/meshes/RElbowYaw_0.10.stl" scale="0.1 0.1 0.1"/>
      </geometry>
      <origin rpy="0 0 0" xyz="0 0 0"/>
    </collision>
  </link>
  
  <joint name="RElbowYaw" type="revolute">
    <parent link="RBicep"/>
    <child link="RElbow"/>
    <origin rpy="0 -0.157079 0" xyz="0.1812 -0.015 0.00013"/>
    <axis xyz="1.0 0 0"/>
    <limit effort="5.428" lower="-2.08567" upper="2.08567" velocity="7.33998"/>
  </joint>

  <link name="RForeArm">
    <inertial>
      <mass value="0.16579"/>
      <inertia ixx="0.00156513" ixy="-1.47517e-05" ixz="-6.05746e-05" iyy="0.00173219" iyz="1.7619e-07" izz="0.000273081"/>
      <origin rpy="0 0 0" xyz="0.0593 -0.00271 -0.01014"/>
    </inertial>
    <visual>
      <geometry>
        <mesh filename="package://pepper_description/meshes/RElbowRoll.dae" scale="0.1 0.1 0.1"/>
      </geometry>
      <origin rpy="0 0 0" xyz="0 0 0"/>
    </visual>
    <collision>
      <geometry>
        <mesh filename="package://pepper_description/meshes/RElbowRoll_0.10.stl" scale="0.1 0.1 0.1"/>
      </geometry>
      <origin rpy="0 0 0" xyz="0 0 0"/>
    </collision>
  </link>
  
  <joint name="RElbowRoll" type="revolute">
    <parent link="RElbow"/>
    <child link="RForeArm"/>
    <origin rpy="0 0 0" xyz="0 0 0"/>
    <axis xyz="0 0 1.0"/>
    <limit effort="2.666" lower="0.00872665" upper="1.56207" velocity="9.22756"/>
  </joint>

  <link name="r_wrist">
    <inertial>
      <mass value="0.27555"/>
      <inertia ixx="0.000151643" ixy="-1.06629e-05" ixz="2.89509e-06" iyy="0.000431099" iyz="3.13715e-06" izz="0.000456172"/>
      <origin rpy="0 0 0" xyz="0.03536 0.00072 -0.00207"/>
    </inertial>
    <visual>
      <geometry>
        <mesh filename="package://pepper_description/meshes/RWristYaw.dae" scale="0.1 0.1 0.1"/>
      </geometry>
      <origin rpy="0 0 0" xyz="0 0 0"/>
    </visual>
    <collision>
      <geometry>
        <mesh filename="package://pepper_description/meshes/RWristYaw_0.10.stl" scale="0.1 0.1 0.1"/>
      </geometry>
      <origin rpy="0 0 0" xyz="0 0 0"/>
    </collision>
  </link>
  
  <joint name="RWristYaw" type="revolute">
    <parent link="RForeArm"/>
    <child link="r_wrist"/>
    <origin rpy="0 0 0" xyz="0.15 0 0"/>
    <axis xyz="1.0 0 0"/>
    <limit effort="0.2014" lower="-1.82387" upper="1.82387" velocity="17.3835"/>
  </joint>

  <link name="WheelFL_link">
    <inertial>
      <mass value="1.58028"/>
      <inertia ixx="0.00299756" ixy="6.3068e-07" ixz="5.56903e-06" iyy="0.00303229" iyz="-9.0408e-07" izz="0.00296585"/>
      <origin rpy="0 0 0" xyz="0 0 0"/>
    </inertial>
    <visual>
      <geometry>
        <mesh filename="package://pepper_description/meshes/WheelFL.dae" scale="0.1 0.1 0.1"/>
      </geometry>
      <origin rpy="0 0 0" xyz="0 0 0"/>
    </visual>
    <collision>
      <geometry>
        <mesh filename="package://pepper_description/meshes/WheelFL_0.10.stl" scale="0.1 0.1 0.1"/>
      </geometry>
      <origin rpy="0 0 0" xyz="0 0 0"/>
    </collision>
  </link>
  <joint name="WheelFL" type="fixed">
    <parent link="Tibia"/>
    <child link="WheelFL_link"/>
    <origin rpy="0 0 1.07517" xyz="0.09 0.155 -0.264"/>
    <axis xyz="1.0 0 0"/>
    <limit effort="3.25" lower="0" upper="0" velocity="6.28319"/>
  </joint>
  <link name="WheelB_link">
    <inertial>
      <mass value="1.58028"/>
      <inertia ixx="0.00299756" ixy="6.3068e-07" ixz="5.56903e-06" iyy="0.00303229" iyz="-9.0408e-07" izz="0.00296585"/>
      <origin rpy="0 0 0" xyz="0 0 0"/>
    </inertial>
    <visual>
      <geometry>
        <mesh filename="package://pepper_description/meshes/WheelB.dae" scale="0.1 0.1 0.1"/>
      </geometry>
      <origin rpy="0 0 0" xyz="0 0 0"/>
    </visual>
    <collision>
      <geometry>
        <mesh filename="package://pepper_description/meshes/WheelB_0.10.stl" scale="0.1 0.1 0.1"/>
      </geometry>
      <origin rpy="0 0 0" xyz="0 0 0"/>
    </collision>
  </link>
  <joint name="WheelB" type="fixed">
    <parent link="Tibia"/>
    <child link="WheelB_link"/>
    <origin rpy="0 0 -3.14159" xyz="-0.17 0 -0.264"/>
    <axis xyz="1.0 0 0"/>
    <limit effort="3.25" lower="0" upper="0" velocity="6.28319"/>
  </joint>
  <link name="WheelFR_link">
    <inertial>
      <mass value="1.58028"/>
      <inertia ixx="0.00299756" ixy="6.3068e-07" ixz="5.56903e-06" iyy="0.00303229" iyz="-9.0408e-07" izz="0.00296585"/>
      <origin rpy="0 0 0" xyz="0 0 0"/>
    </inertial>
    <visual>
      <geometry>
        <mesh filename="package://pepper_description/meshes/WheelFR.dae" scale="0.1 0.1 0.1"/>
      </geometry>
      <origin rpy="0 0 0" xyz="0 0 0"/>
    </visual>
    <collision>
      <geometry>
        <mesh filename="package://pepper_description/meshes/WheelFR_0.10.stl" scale="0.1 0.1 0.1"/>
      </geometry>
      <origin rpy="0 0 0" xyz="0 0 0"/>
    </collision>
  </link>
  <joint name="WheelFR" type="fixed">
    <parent link="Tibia"/>
    <child link="WheelFR_link"/>
    <origin rpy="0 0 -1.07517" xyz="0.09 -0.155 -0.264"/>
    <axis xyz="1.0 0 0"/>
    <limit effort="3.25" lower="0" upper="0" velocity="6.28319"/>
  </joint>
</robot>